[2024-11-20T10:00:45.556+0000] {taskinstance.py:1157} INFO - Dependencies all met for dep_context=non-requeueable deps ti=<TaskInstance: wikipedia_flow.transform_wikipedia_data manual__2024-11-20T10:00:40.601356+00:00 [queued]>
[2024-11-20T10:00:45.560+0000] {taskinstance.py:1157} INFO - Dependencies all met for dep_context=requeueable deps ti=<TaskInstance: wikipedia_flow.transform_wikipedia_data manual__2024-11-20T10:00:40.601356+00:00 [queued]>
[2024-11-20T10:00:45.560+0000] {taskinstance.py:1359} INFO - Starting attempt 1 of 1
[2024-11-20T10:00:45.565+0000] {taskinstance.py:1380} INFO - Executing <Task(PythonOperator): transform_wikipedia_data> on 2024-11-20 10:00:40.601356+00:00
[2024-11-20T10:00:45.567+0000] {standard_task_runner.py:57} INFO - Started process 126 to run task
[2024-11-20T10:00:45.569+0000] {standard_task_runner.py:84} INFO - Running: ['***', 'tasks', 'run', 'wikipedia_flow', 'transform_wikipedia_data', 'manual__2024-11-20T10:00:40.601356+00:00', '--job-id', '3', '--raw', '--subdir', 'DAGS_FOLDER/wikipedia.py', '--cfg-path', '/tmp/tmp1m7plw1u']
[2024-11-20T10:00:45.571+0000] {standard_task_runner.py:85} INFO - Job 3: Subtask transform_wikipedia_data
[2024-11-20T10:00:45.599+0000] {task_command.py:415} INFO - Running <TaskInstance: wikipedia_flow.transform_wikipedia_data manual__2024-11-20T10:00:40.601356+00:00 [running]> on host scheduler
[2024-11-20T10:00:45.713+0000] {taskinstance.py:1660} INFO - Exporting env vars: AIRFLOW_CTX_DAG_OWNER='ClarkSon Tech' AIRFLOW_CTX_DAG_ID='wikipedia_flow' AIRFLOW_CTX_TASK_ID='transform_wikipedia_data' AIRFLOW_CTX_EXECUTION_DATE='2024-11-20T10:00:40.601356+00:00' AIRFLOW_CTX_TRY_NUMBER='1' AIRFLOW_CTX_DAG_RUN_ID='manual__2024-11-20T10:00:40.601356+00:00'
[2024-11-20T10:08:29.808+0000] {process_utils.py:131} INFO - Sending 15 to group 126. PIDs of all processes in the group: [126]
[2024-11-20T10:08:29.811+0000] {process_utils.py:86} INFO - Sending the signal 15 to group 126
[2024-11-20T10:08:29.812+0000] {taskinstance.py:1630} ERROR - Received SIGTERM. Terminating subprocesses.
[2024-11-20T10:08:29.815+0000] {logging_mixin.py:151} INFO - Error while geocoding Taizhou Sports Centre Stadium, China: Task received SIGTERM signal
[2024-11-20T10:08:49.428+0000] {taskinstance.py:1935} ERROR - Task failed with exception
Traceback (most recent call last):
  File "/home/airflow/.local/lib/python3.9/site-packages/airflow/operators/python.py", line 192, in execute
    return_value = self.execute_callable()
  File "/home/airflow/.local/lib/python3.9/site-packages/airflow/operators/python.py", line 209, in execute_callable
    return self.python_callable(*self.op_args, **self.op_kwargs)
  File "/opt/airflow/pipelines/wikipedia_pipeline.py", line 113, in transform_wikipedia_data
    # kwargs['ti'].xcom_push(key='rows', value=stadiums_df.to_json())
  File "/home/airflow/.local/lib/python3.9/site-packages/airflow/utils/session.py", line 77, in wrapper
    return func(*args, session=session, **kwargs)
  File "/home/airflow/.local/lib/python3.9/site-packages/airflow/models/taskinstance.py", line 2477, in xcom_push
    XCom.set(
  File "/home/airflow/.local/lib/python3.9/site-packages/airflow/utils/session.py", line 74, in wrapper
    return func(*args, **kwargs)
  File "/home/airflow/.local/lib/python3.9/site-packages/airflow/models/xcom.py", line 221, in set
    raise ValueError(f"DAG run not found on DAG {dag_id!r} with ID {run_id!r}")
ValueError: DAG run not found on DAG 'wikipedia_flow' with ID 'manual__2024-11-20T10:00:40.601356+00:00'
[2024-11-20T10:08:49.440+0000] {taskinstance.py:1398} INFO - Marking task as FAILED. dag_id=wikipedia_flow, task_id=transform_wikipedia_data, execution_date=20241120T100040, start_date=20241120T100045, end_date=20241120T100849
[2024-11-20T10:08:49.449+0000] {standard_task_runner.py:104} ERROR - Failed to execute job 3 for task transform_wikipedia_data ((psycopg2.errors.ForeignKeyViolation) insert or update on table "task_fail" violates foreign key constraint "task_fail_ti_fkey"
DETAIL:  Key (dag_id, task_id, run_id, map_index)=(wikipedia_flow, transform_wikipedia_data, manual__2024-11-20T10:00:40.601356+00:00, -1) is not present in table "task_instance".

[SQL: INSERT INTO task_fail (task_id, dag_id, run_id, map_index, start_date, end_date, duration) VALUES (%(task_id)s, %(dag_id)s, %(run_id)s, %(map_index)s, %(start_date)s, %(end_date)s, %(duration)s) RETURNING task_fail.id]
[parameters: {'task_id': 'transform_wikipedia_data', 'dag_id': 'wikipedia_flow', 'run_id': 'manual__2024-11-20T10:00:40.601356+00:00', 'map_index': -1, 'start_date': datetime.datetime(2024, 11, 20, 10, 0, 45, 556791, tzinfo=Timezone('UTC')), 'end_date': datetime.datetime(2024, 11, 20, 10, 8, 49, 439444, tzinfo=Timezone('UTC')), 'duration': 483}]
(Background on this error at: https://sqlalche.me/e/14/gkpj); 126)
[2024-11-20T10:08:49.474+0000] {process_utils.py:79} INFO - Process psutil.Process(pid=126, status='terminated', exitcode=1, started='10:00:45') (126) terminated with exit code 1
